$ python -m uvicorn resync.mainapp --host 0.0.0.0 --port 8000
Traceback (most recent call last)
  File frozen runpy, line 198, in _run_module_as_main
  File frozen runpy, line 88, in _run_code
  File CUsersUserAppDataLocalProgramsPythonPython313Libsite-packagesuvicorn__main__.py, line 4, in module
    uvicorn.main()
    ~~~~~~~~~~~~^^
  File CUsersUserAppDataLocalProgramsPythonPython313Libsite-packagesclickcore.py, line 1161, in __call__
    return self.main(args, kwargs)
           ~~~~~~~~~^^^^^^^^^^^^^^^^^
  File CUsersUserAppDataLocalProgramsPythonPython313Libsite-packagesclickcore.py, line 1082, in main
    rv = self.invoke(ctx)
  File CUsersUserAppDataLocalProgramsPythonPython313Libsite-packagesclickcore.py, line 1443, in invoke
    return ctx.invoke(self.callback, ctx.params)
           ~~~~~~~~~~^^^^^^^^^^^^^^^^^^^^^^^^^^^^^
  File CUsersUserAppDataLocalProgramsPythonPython313Libsite-packagesclickcore.py, line 788, in invoke
    return __callback(args, kwargs)
  File CUsersUserAppDataLocalProgramsPythonPython313Libsite-packagesuvicornmain.py, line 423, in main
    run(
    ~~~^
        app,
        ^^^^
    ...46 lines...
        h11_max_incomplete_event_size=h11_max_incomplete_event_size,
        ^^^^^^^^^^^^^^^^^^^^^^^^^^^^^^^^^^^^^^^^^^^^^^^^^^^^^^^^^^^^
    )
    ^
  File CUsersUserAppDataLocalProgramsPythonPython313Libsite-packagesuvicornmain.py, line 593, in run
    server.run()
    ~~~~~~~~~~^^
  File CUsersUserAppDataLocalProgramsPythonPython313Libsite-packagesuvicornserver.py, line 67, in run
    return asyncio_run(self.serve(sockets=sockets), loop_factory=self.config.get_loop_factory())
  File CUsersUserAppDataLocalProgramsPythonPython313Libasynciorunners.py, line 195, in run
    return runner.run(main)
           ~~~~~~~~~~^^^^^^
  File CUsersUserAppDataLocalProgramsPythonPython313Libasynciorunners.py, line 118, in run
    return self._loop.run_until_complete(task)
           ~~~~~~~~~~~~~~~~~~~~~~~~~~~~~^^^^^^
  File CUsersUserAppDataLocalProgramsPythonPython313Libasynciobase_events.py, line 725, in run_until_complete
    return future.result()
           ~~~~~~~~~~~~~^^
  File CUsersUserAppDataLocalProgramsPythonPython313Libsite-packagesuvicornserver.py, line 71, in serve
    await self._serve(sockets)
  File CUsersUserAppDataLocalProgramsPythonPython313Libsite-packagesuvicornserver.py, line 78, in _serve
    config.load()
    ~~~~~~~~~~~^^
  File CUsersUserAppDataLocalProgramsPythonPython313Libsite-packagesuvicornconfig.py, line 438, in load
    self.loaded_app = import_from_string(self.app)
                      ~~~~~~~~~~~~~~~~~~^^^^^^^^^^
  File CUsersUserAppDataLocalProgramsPythonPython313Libsite-packagesuvicornimporter.py, line 19, in import_from_string
    module = importlib.import_module(module_str)
  File CUsersUserAppDataLocalProgramsPythonPython313Libimportlib__init__.py, line 88, in import_module
    return _bootstrap._gcd_import(name[level], package, level)
           ~~~~~~~~~~~~~~~~~~~~~~^^^^^^^^^^^^^^^^^^^^^^^^^^^^^^
  File frozen importlib._bootstrap, line 1387, in _gcd_import
  File frozen importlib._bootstrap, line 1360, in _find_and_load
  File frozen importlib._bootstrap, line 1331, in _find_and_load_unlocked
  File frozen importlib._bootstrap, line 935, in _load_unlocked
  File frozen importlib._bootstrap_external, line 1026, in exec_module
  File frozen importlib._bootstrap, line 488, in _call_with_frames_removed
  File DPythonGITHUBhwa-newresyncmain.py, line 3, in module
    from resync.app_factory import create_app
  File DPythonGITHUBhwa-newresyncapp_factory.py, line 22, in module
    from resync.settings import settings
  File DPythonGITHUBhwa-newresyncsettings.py, line 40, in module
    class Settings(BaseSettings)
    ...668 lines...
                    )
  File DPythonGITHUBhwa-newresyncsettings.py, line 190, in Settings
    default=int(os.environ.get(CACHE_HIERARCHY_L1_MAX_SIZE, 5000)),
                ^^
NameError name 'os' is not defined. Did you forget to import 'os'
$ 


Correção proposta abaixo

## Análise do Problema

O erro é bem claro o módulo `os` não foi importado no arquivo `resyncsettings.py`, mas está sendo usado na linha 190 para acessar `os.environ.get()`.

## Solução

Adicione o import do módulo `os` no início do arquivo `resyncsettings.py`

```python
import os
```

### Localização do Import

O import deve ser adicionado no topo do arquivo, geralmente após os imports do Python padrão e antes dos imports de terceiros. Uma estrutura típica seria

```python
# Imports do Python padrão
import os
from typing import Optional, List
# ... outros imports padrão

# Imports de terceiros
from pydantic import BaseSettings
# ... outros imports de terceiros

# Imports locais
# ... seus imports locais
```

## Verificação Completa

Para garantir que não há outros problemas similares, verifique se o arquivo `settings.py` possui todos os imports necessários no início

```python
import os
from typing import Optional, Any, Dict
from pydantic import BaseSettings, Field
# ... outros imports que você esteja usando
```

## Próximos Passos

1. Adicione `import os` no início de `resyncsettings.py`
2. Salve o arquivo
3. Execute o comando novamente
   ```bash
   python -m uvicorn resync.mainapp --host 0.0.0.0 --port 8000
   ```

Nota Se você estiver usando outras variáveis de ambiente no arquivo (como `os.getenv()` ou `os.path`), o mesmo import resolverá todos esses casos.

Precisa de ajuda com algum outro erro que possa aparecer após essa correção